Workbook

Sheet DASHBOARD
A1: Latest Comparison
A3: Company | B3: Download MoM Growth | C3: Download 3M Growth | D3: Download 6M Growth | E3: Star Growth (30d) | F3: Fork Growth (30d) | G3: Trends (latest, 0-100)
A4: {=IFERROR( _xlfn.LET( _xlpm.filtered, _xlfn.UNIQUE(_xlfn._xlws.FILTER(Config!$A$1:$A$498, Config!$G$1:$G$498="Y")), INDEX(_xlpm.filtered, ROW()-ROW($A$2)+1) ), "" )} | B4: =IFERROR(_xlfn.SINGLE(_xlfn.XLOOKUP($A4,ProxyCalc[Company],ProxyCalc[Download MoM Growth],,0)),"") | C4: =IFERROR(_xlfn.SINGLE(_xlfn.XLOOKUP($A4,ProxyCalc[Company],ProxyCalc[Download 3M Growth],,0)),"") | D4: =IFERROR(_xlfn.SINGLE(_xlfn.XLOOKUP($A4,ProxyCalc[Company],ProxyCalc[Download 6M Growth],,0)),"") | E4: =IFERROR(_xlfn.SINGLE(_xlfn.XLOOKUP($A4,ProxyCalc[Company],ProxyCalc[Star Growth (30d)])),"") | F4: =IFERROR(_xlfn.SINGLE(_xlfn.XLOOKUP($A4,ProxyCalc[Company],ProxyCalc[Fork Growth (30d)])),"") | G4: =IFERROR(_xlfn.SINGLE(_xlfn.XLOOKUP($A4,ProxyCalc[Company],ProxyCalc[Trends Index (latest)])),"")
A5: {=IFERROR( _xlfn.LET( _xlpm.filtered, _xlfn.UNIQUE(_xlfn._xlws.FILTER(Config!$A$1:$A$498, Config!$G$1:$G$498="Y")), INDEX(_xlpm.filtered, ROW()-ROW($A$2)+1) ), "" )} | B5: =IFERROR(_xlfn.SINGLE(_xlfn.XLOOKUP($A5,ProxyCalc[Company],ProxyCalc[Download MoM Growth],,0)),"") | C5: =IFERROR(_xlfn.SINGLE(_xlfn.XLOOKUP($A5,ProxyCalc[Company],ProxyCalc[Download 3M Growth],,0)),"") | D5: =IFERROR(_xlfn.SINGLE(_xlfn.XLOOKUP($A5,ProxyCalc[Company],ProxyCalc[Download 6M Growth],,0)),"") | E5: =IFERROR(_xlfn.SINGLE(_xlfn.XLOOKUP($A5,ProxyCalc[Company],ProxyCalc[Star Growth (30d)])),"") | F5: =IFERROR(_xlfn.SINGLE(_xlfn.XLOOKUP($A5,ProxyCalc[Company],ProxyCalc[Fork Growth (30d)])),"") | G5: =IFERROR(_xlfn.SINGLE(_xlfn.XLOOKUP($A5,ProxyCalc[Company],ProxyCalc[Trends Index (latest)])),"")
A6: {=IFERROR( _xlfn.LET( _xlpm.filtered, _xlfn.UNIQUE(_xlfn._xlws.FILTER(Config!$A$1:$A$498, Config!$G$1:$G$498="Y")), INDEX(_xlpm.filtered, ROW()-ROW($A$2)+1) ), "" )} | B6: =IFERROR(_xlfn.SINGLE(_xlfn.XLOOKUP($A6,ProxyCalc[Company],ProxyCalc[Download MoM Growth],,0)),"") | C6: =IFERROR(_xlfn.SINGLE(_xlfn.XLOOKUP($A6,ProxyCalc[Company],ProxyCalc[Download 3M Growth],,0)),"") | D6: =IFERROR(_xlfn.SINGLE(_xlfn.XLOOKUP($A6,ProxyCalc[Company],ProxyCalc[Download 6M Growth],,0)),"") | E6: =IFERROR(_xlfn.SINGLE(_xlfn.XLOOKUP($A6,ProxyCalc[Company],ProxyCalc[Star Growth (30d)])),"") | F6: =IFERROR(_xlfn.SINGLE(_xlfn.XLOOKUP($A6,ProxyCalc[Company],ProxyCalc[Fork Growth (30d)])),"") | G6: =IFERROR(_xlfn.SINGLE(_xlfn.XLOOKUP($A6,ProxyCalc[Company],ProxyCalc[Trends Index (latest)])),"")
A7: {=IFERROR( _xlfn.LET( _xlpm.filtered, _xlfn.UNIQUE(_xlfn._xlws.FILTER(Config!$A$1:$A$498, Config!$G$1:$G$498="Y")), INDEX(_xlpm.filtered, ROW()-ROW($A$2)+1) ), "" )} | B7: =IFERROR(_xlfn.SINGLE(_xlfn.XLOOKUP($A7,ProxyCalc[Company],ProxyCalc[Download MoM Growth],,0)),"") | C7: =IFERROR(_xlfn.SINGLE(_xlfn.XLOOKUP($A7,ProxyCalc[Company],ProxyCalc[Download 3M Growth],,0)),"") | D7: =IFERROR(_xlfn.SINGLE(_xlfn.XLOOKUP($A7,ProxyCalc[Company],ProxyCalc[Download 6M Growth],,0)),"") | E7: =IFERROR(_xlfn.SINGLE(_xlfn.XLOOKUP($A7,ProxyCalc[Company],ProxyCalc[Star Growth (30d)])),"") | F7: =IFERROR(_xlfn.SINGLE(_xlfn.XLOOKUP($A7,ProxyCalc[Company],ProxyCalc[Fork Growth (30d)])),"") | G7: =IFERROR(_xlfn.SINGLE(_xlfn.XLOOKUP($A7,ProxyCalc[Company],ProxyCalc[Trends Index (latest)])),"")
A8: {=IFERROR( _xlfn.LET( _xlpm.filtered, _xlfn.UNIQUE(_xlfn._xlws.FILTER(Config!$A$1:$A$498, Config!$G$1:$G$498="Y")), INDEX(_xlpm.filtered, ROW()-ROW($A$2)+1) ), "" )} | B8: =IFERROR(_xlfn.SINGLE(_xlfn.XLOOKUP($A8,ProxyCalc[Company],ProxyCalc[Download MoM Growth],,0)),"") | C8: =IFERROR(_xlfn.SINGLE(_xlfn.XLOOKUP($A8,ProxyCalc[Company],ProxyCalc[Download 3M Growth],,0)),"") | D8: =IFERROR(_xlfn.SINGLE(_xlfn.XLOOKUP($A8,ProxyCalc[Company],ProxyCalc[Download 6M Growth],,0)),"") | E8: =IFERROR(_xlfn.SINGLE(_xlfn.XLOOKUP($A8,ProxyCalc[Company],ProxyCalc[Star Growth (30d)])),"") | F8: =IFERROR(_xlfn.SINGLE(_xlfn.XLOOKUP($A8,ProxyCalc[Company],ProxyCalc[Fork Growth (30d)])),"") | G8: =IFERROR(_xlfn.SINGLE(_xlfn.XLOOKUP($A8,ProxyCalc[Company],ProxyCalc[Trends Index (latest)])),"")
A9: {=IFERROR( _xlfn.LET( _xlpm.filtered, _xlfn.UNIQUE(_xlfn._xlws.FILTER(Config!$A$1:$A$498, Config!$G$1:$G$498="Y")), INDEX(_xlpm.filtered, ROW()-ROW($A$2)+1) ), "" )} | B9: =IFERROR(_xlfn.SINGLE(_xlfn.XLOOKUP($A9,ProxyCalc[Company],ProxyCalc[Download MoM Growth],,0)),"") | C9: =IFERROR(_xlfn.SINGLE(_xlfn.XLOOKUP($A9,ProxyCalc[Company],ProxyCalc[Download 3M Growth],,0)),"") | D9: =IFERROR(_xlfn.SINGLE(_xlfn.XLOOKUP($A9,ProxyCalc[Company],ProxyCalc[Download 6M Growth],,0)),"") | E9: =IFERROR(_xlfn.SINGLE(_xlfn.XLOOKUP($A9,ProxyCalc[Company],ProxyCalc[Star Growth (30d)])),"") | F9: =IFERROR(_xlfn.SINGLE(_xlfn.XLOOKUP($A9,ProxyCalc[Company],ProxyCalc[Fork Growth (30d)])),"") | G9: =IFERROR(_xlfn.SINGLE(_xlfn.XLOOKUP($A9,ProxyCalc[Company],ProxyCalc[Trends Index (latest)])),"")
A10: {=IFERROR( _xlfn.LET( _xlpm.filtered, _xlfn.UNIQUE(_xlfn._xlws.FILTER(Config!$A$1:$A$498, Config!$G$1:$G$498="Y")), INDEX(_xlpm.filtered, ROW()-ROW($A$2)+1) ), "" )} | B10: =IFERROR(_xlfn.SINGLE(_xlfn.XLOOKUP($A10,ProxyCalc[Company],ProxyCalc[Download MoM Growth],,0)),"") | C10: =IFERROR(_xlfn.SINGLE(_xlfn.XLOOKUP($A10,ProxyCalc[Company],ProxyCalc[Download 3M Growth],,0)),"") | D10: =IFERROR(_xlfn.SINGLE(_xlfn.XLOOKUP($A10,ProxyCalc[Company],ProxyCalc[Download 6M Growth],,0)),"") | E10: =IFERROR(_xlfn.SINGLE(_xlfn.XLOOKUP($A10,ProxyCalc[Company],ProxyCalc[Star Growth (30d)])),"") | F10: =IFERROR(_xlfn.SINGLE(_xlfn.XLOOKUP($A10,ProxyCalc[Company],ProxyCalc[Fork Growth (30d)])),"") | G10: =IFERROR(_xlfn.SINGLE(_xlfn.XLOOKUP($A10,ProxyCalc[Company],ProxyCalc[Trends Index (latest)])),"")
A11: {=IFERROR( _xlfn.LET( _xlpm.filtered, _xlfn.UNIQUE(_xlfn._xlws.FILTER(Config!$A$1:$A$498, Config!$G$1:$G$498="Y")), INDEX(_xlpm.filtered, ROW()-ROW($A$2)+1) ), "" )} | B11: =IFERROR(_xlfn.SINGLE(_xlfn.XLOOKUP($A11,ProxyCalc[Company],ProxyCalc[Download MoM Growth],,0)),"") | C11: =IFERROR(_xlfn.SINGLE(_xlfn.XLOOKUP($A11,ProxyCalc[Company],ProxyCalc[Download 3M Growth],,0)),"") | D11: =IFERROR(_xlfn.SINGLE(_xlfn.XLOOKUP($A11,ProxyCalc[Company],ProxyCalc[Download 6M Growth],,0)),"") | E11: =IFERROR(_xlfn.SINGLE(_xlfn.XLOOKUP($A11,ProxyCalc[Company],ProxyCalc[Star Growth (30d)])),"") | F11: =IFERROR(_xlfn.SINGLE(_xlfn.XLOOKUP($A11,ProxyCalc[Company],ProxyCalc[Fork Growth (30d)])),"") | G11: =IFERROR(_xlfn.SINGLE(_xlfn.XLOOKUP($A11,ProxyCalc[Company],ProxyCalc[Trends Index (latest)])),"")
A12: {=IFERROR( _xlfn.LET( _xlpm.filtered, _xlfn.UNIQUE(_xlfn._xlws.FILTER(Config!$A$1:$A$498, Config!$G$1:$G$498="Y")), INDEX(_xlpm.filtered, ROW()-ROW($A$2)+1) ), "" )} | B12: =IFERROR(_xlfn.SINGLE(_xlfn.XLOOKUP($A12,ProxyCalc[Company],ProxyCalc[Download MoM Growth],,0)),"") | C12: =IFERROR(_xlfn.SINGLE(_xlfn.XLOOKUP($A12,ProxyCalc[Company],ProxyCalc[Download 3M Growth],,0)),"") | D12: =IFERROR(_xlfn.SINGLE(_xlfn.XLOOKUP($A12,ProxyCalc[Company],ProxyCalc[Download 6M Growth],,0)),"") | E12: =IFERROR(_xlfn.SINGLE(_xlfn.XLOOKUP($A12,ProxyCalc[Company],ProxyCalc[Star Growth (30d)])),"") | F12: =IFERROR(_xlfn.SINGLE(_xlfn.XLOOKUP($A12,ProxyCalc[Company],ProxyCalc[Fork Growth (30d)])),"") | G12: =IFERROR(_xlfn.SINGLE(_xlfn.XLOOKUP($A12,ProxyCalc[Company],ProxyCalc[Trends Index (latest)])),"")
A13: {=IFERROR( _xlfn.LET( _xlpm.filtered, _xlfn.UNIQUE(_xlfn._xlws.FILTER(Config!$A$1:$A$498, Config!$G$1:$G$498="Y")), INDEX(_xlpm.filtered, ROW()-ROW($A$2)+1) ), "" )} | B13: =IFERROR(_xlfn.SINGLE(_xlfn.XLOOKUP($A13,ProxyCalc[Company],ProxyCalc[Download MoM Growth],,0)),"") | C13: =IFERROR(_xlfn.SINGLE(_xlfn.XLOOKUP($A13,ProxyCalc[Company],ProxyCalc[Download 3M Growth],,0)),"") | D13: =IFERROR(_xlfn.SINGLE(_xlfn.XLOOKUP($A13,ProxyCalc[Company],ProxyCalc[Download 6M Growth],,0)),"") | E13: =IFERROR(_xlfn.SINGLE(_xlfn.XLOOKUP($A13,ProxyCalc[Company],ProxyCalc[Star Growth (30d)])),"") | F13: =IFERROR(_xlfn.SINGLE(_xlfn.XLOOKUP($A13,ProxyCalc[Company],ProxyCalc[Fork Growth (30d)])),"") | G13: =IFERROR(_xlfn.SINGLE(_xlfn.XLOOKUP($A13,ProxyCalc[Company],ProxyCalc[Trends Index (latest)])),"")
A14: {=IFERROR( _xlfn.LET( _xlpm.filtered, _xlfn.UNIQUE(_xlfn._xlws.FILTER(Config!$A$1:$A$498, Config!$G$1:$G$498="Y")), INDEX(_xlpm.filtered, ROW()-ROW($A$2)+1) ), "" )} | B14: =IFERROR(_xlfn.SINGLE(_xlfn.XLOOKUP($A14,ProxyCalc[Company],ProxyCalc[Download MoM Growth],,0)),"") | C14: =IFERROR(_xlfn.SINGLE(_xlfn.XLOOKUP($A14,ProxyCalc[Company],ProxyCalc[Download 3M Growth],,0)),"") | D14: =IFERROR(_xlfn.SINGLE(_xlfn.XLOOKUP($A14,ProxyCalc[Company],ProxyCalc[Download 6M Growth],,0)),"") | E14: =IFERROR(_xlfn.SINGLE(_xlfn.XLOOKUP($A14,ProxyCalc[Company],ProxyCalc[Star Growth (30d)])),"") | F14: =IFERROR(_xlfn.SINGLE(_xlfn.XLOOKUP($A14,ProxyCalc[Company],ProxyCalc[Fork Growth (30d)])),"") | G14: =IFERROR(_xlfn.SINGLE(_xlfn.XLOOKUP($A14,ProxyCalc[Company],ProxyCalc[Trends Index (latest)])),"")
A15: {=IFERROR( _xlfn.LET( _xlpm.filtered, _xlfn.UNIQUE(_xlfn._xlws.FILTER(Config!$A$1:$A$498, Config!$G$1:$G$498="Y")), INDEX(_xlpm.filtered, ROW()-ROW($A$2)+1) ), "" )} | B15: =IFERROR(_xlfn.SINGLE(_xlfn.XLOOKUP($A15,ProxyCalc[Company],ProxyCalc[Download MoM Growth],,0)),"") | C15: =IFERROR(_xlfn.SINGLE(_xlfn.XLOOKUP($A15,ProxyCalc[Company],ProxyCalc[Download 3M Growth],,0)),"") | D15: =IFERROR(_xlfn.SINGLE(_xlfn.XLOOKUP($A15,ProxyCalc[Company],ProxyCalc[Download 6M Growth],,0)),"") | E15: =IFERROR(_xlfn.SINGLE(_xlfn.XLOOKUP($A15,ProxyCalc[Company],ProxyCalc[Star Growth (30d)])),"") | F15: =IFERROR(_xlfn.SINGLE(_xlfn.XLOOKUP($A15,ProxyCalc[Company],ProxyCalc[Fork Growth (30d)])),"") | G15: =IFERROR(_xlfn.SINGLE(_xlfn.XLOOKUP($A15,ProxyCalc[Company],ProxyCalc[Trends Index (latest)])),"")
... A58: {=IFERROR( _xlfn.LET( _xlpm.filtered, _xlfn.UNIQUE(_xlfn._xlws.FILTER(Config!$A$1:$A$498, Config!$G$1:$G$498="Y")), INDEX(_xlpm.filtered, ROW()-ROW($A$2)+1) ), "" )} | B58: =IFERROR(_xlfn.SINGLE(_xlfn.XLOOKUP($A58,ProxyCalc[Company],ProxyCalc[Download MoM Growth],,0)),"") | C58: =IFERROR(_xlfn.SINGLE(_xlfn.XLOOKUP($A58,ProxyCalc[Company],ProxyCalc[Download 3M Growth],,0)),"") | D58: =IFERROR(_xlfn.SINGLE(_xlfn.XLOOKUP($A58,ProxyCalc[Company],ProxyCalc[Download 6M Growth],,0)),"") | E58: =IFERROR(_xlfn.SINGLE(_xlfn.XLOOKUP($A58,ProxyCalc[Company],ProxyCalc[Star Growth (30d)])),"") | F58: =IFERROR(_xlfn.SINGLE(_xlfn.XLOOKUP($A58,ProxyCalc[Company],ProxyCalc[Fork Growth (30d)])),"") | G58: =IFERROR(_xlfn.SINGLE(_xlfn.XLOOKUP($A58,ProxyCalc[Company],ProxyCalc[Trends Index (latest)])),"")

Sheet README
A1: Quantum Platform Telemetry Model
A3: What this workbook does
A4: • Stores time-series snapshots from GitHub + PyPI + Google Trends
A5: • Computes growth (WoW/MoM), activity proxies per company
A6: • Lets you compare different quantum python libraries
A8: How to run automation
A9: 1) Fill in the Config sheet (repos, packages, domains, trend keywords, GitHub token).
A10: 2) Run update_telemetry_free.py weekly (cron / Task Scheduler). It appends snapshots.
A11: 3) Open Dashboard sheet for latest metrics and trend deltas.
A13: Notes / limitations
A14: • GitHub/PyPI/Trends are developer & interest proxies, not true product MAU.
A15: • Google Trends values are relative to the keyword set in the query (0–100). Keep the keyword set stable.
... A24: launchctl unload ~/Library/LaunchAgents/com.telemetry.weekly.plist

Sheet Config
A1: Inputs
A3: Global settings
A4: GitHub Token (classic PAT) | B4: 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
A5: Snapshot frequency (days) | B5: 7
A7: Proxy coefficients
A8: k_monthly_contributors | B8: 40
A9: k_monthly_issue_authors | B9: 25
A10: k_monthly_star_growth | B10: 30
A11: k_monthly_fork_growth | B11: 20
A12: wau_factor_low | B12: 0.2
A13: wau_factor_high | B13: 0.35
A15: Google Trends settings (free)
A16: Geo (leave blank = worldwide)
A17: Timeframe (e.g., today 3-m, today 12-m, today 5-y) | B17: today 12-m
A18: Sampling method | B18: weekly_avg
A20: Company → Repos / Packages / Trend Keywords (add rows as needed)
A21: Company | B21: Type | C21: GitHub Owner | D21: Repo | E21: PyPI Package | F21: Trend Keyword | G21: Include? (Y/N)
A22: Qiskit Community | B22: SDK | C22: Qiskit | D22: qiskit | E22: qiskit | F22: qiskit | G22: Y
A23: Qiskit Community | B23: SDK | C23: qiskit-community | D23: qiskit-algorithms | F23: qiskit | G23: Y
A24: AWS Braket | B24: SDK | C24: amazon-braket | D24: amazon-braket-sdk-python | E24: amazon-braket-sdk | F24: amazon braket | G24: Y
A25: qBraid | B25: SDK | C25: qBraid | D25: qBraid | E25: qbraid | F25: qbraid | G25: Y
A26: Aqora | B26: SDK | C26: aqora-io | D26: q3as-py | E26: q3as | F26: aqora | G26: Y
A27: Aqora | B27: SDK | C27: aqora-io | D27: cli | E27: aqora-cli | F27: aqora | G27: Y
A28: IBM | B28: SDK | C28: qiskit | D28: qiskit | E28: qiskit | F28: qiskit | G28: Y
A29: Google | B29: SDK | C29: quantumlib | D29: cirq | E29: cirq | F29: cirq | G29: Y
A30: Xanadu | B30: ML | C30: PennyLaneAI | D30: pennylane | E30: pennylane | F30: pennylane | G30: Y
A31: Amazon Braket | B31: SDK | C31: amazon-braket | D31: amazon-braket-sdk-python | E31: amazon-braket-sdk | F31: amazon braket | G31: Y
A32: D-Wave | B32: Systems | C32: dwavesystems | D32: dwave-ocean-sdk | E32: dwave-ocean-sdk | F32: dwave ocean | G32: Y
A33: Rigetti | B33: SDK | C33: rigetti | D33: pyquil | E33: pyquil | F33: pyquil | G33: Y
A34: Blueqat | B34: SDK | C34: Blueqat | D34: Blueqat | E34: blueqat | F34: blueqat | G34: Y
A35: QuTiP Team | B35: Simulator | C35: qutip | D35: qutip | E35: qutip | F35: qutip | G35: Y
... A86: Microsoft | B86: SDK | C86: Microsoft | D86: qdk | E86: qdk | F86: qdk | G86: N

Sheet GitHub_Snapshots
A1: Snapshot Date | B1: Company | C1: Owner | D1: Repo | E1: Stars | F1: Forks | G1: Open Issues | H1: Open PRs | I1: Commits (7d) | J1: Unique Commit Authors (30d) | K1: Unique Issue Authors (30d) | L1: Unique PR Authors (30d) | M1: Releases (12m)
A2: 46059 | B2: Qiskit Community | C2: Qiskit | D2: qiskit | E2: 7017 | F2: 2762 | G2: 1114 | H2: 100 | I2: 14 | J2: 22 | K2: 99 | L2: 77 | M2: 25
A3: 46059 | B3: Qiskit Community | C3: qiskit-community | D3: qiskit-algorithms | E3: 172 | F3: 75 | G3: 43 | H3: 7 | I3: 0 | J3: 0 | K3: 0 | L3: 2 | M3: 1
A4: 46059 | B4: AWS Braket | C4: amazon-braket | D4: amazon-braket-sdk-python | E4: 354 | F4: 143 | G4: 28 | H4: 7 | I4: 8 | J4: 7 | K4: 7 | L4: 10 | M4: 50
A5: 46059 | B5: qBraid | C5: qBraid | D5: qBraid | E5: 106 | F5: 53 | G5: 43 | H5: 12 | I5: 0 | J5: 3 | K5: 2 | L5: 5 | M5: 9
A6: 46059 | B6: Aqora | C6: aqora-io | D6: q3as-py | E6: 2 | F6: 1 | G6: 0 | H6: 0 | I6: 0 | J6: 0 | K6: 0 | L6: 0 | M6: 0
A7: 46059 | B7: Aqora | C7: aqora-io | D7: cli | E7: 3 | F7: 2 | G7: 6 | H7: 0 | I7: 0 | J7: 1 | K7: 0 | L7: 1 | M7: 0
A8: 46064 | B8: Qiskit Community | C8: Qiskit | D8: qiskit | E8: 7030 | F8: 2760 | G8: 1110 | H8: 100 | I8: 20 | J8: 21 | K8: 97 | L8: 75 | M8: 25
A9: 46064 | B9: Qiskit Community | C9: qiskit-community | D9: qiskit-algorithms | E9: 173 | F9: 75 | G9: 43 | H9: 7 | I9: 0 | J9: 0 | K9: 0 | L9: 2 | M9: 1
A10: 46064 | B10: AWS Braket | C10: amazon-braket | D10: amazon-braket-sdk-python | E10: 355 | F10: 144 | G10: 28 | H10: 7 | I10: 6 | J10: 5 | K10: 6 | L10: 9 | M10: 49
A11: 46064 | B11: qBraid | C11: qBraid | D11: qBraid | E11: 106 | F11: 53 | G11: 42 | H11: 11 | I11: 4 | J11: 4 | K11: 2 | L11: 5 | M11: 11
A12: 46064 | B12: Aqora | C12: aqora-io | D12: q3as-py | E12: 2 | F12: 1 | G12: 0 | H12: 0 | I12: 0 | J12: 0 | K12: 0 | L12: 0 | M12: 0
A13: 46064 | B13: Aqora | C13: aqora-io | D13: cli | E13: 3 | F13: 2 | G13: 8 | H13: 2 | I13: 4 | J13: 2 | K13: 0 | L13: 2 | M13: 0
... A122: 46076 | B122: OpenFermion | C122: quantumlib | D122: OpenFermion-PySCF | E122: 115 | F122: 44 | G122: 12 | H122: 1 | I122: 0 | J122: 0 | K122: 0 | L122: 0 | M122: 0
A123: 46076 | B123: Cirq-Quantum Volume | C123: quantumlib | D123: qdesign
A124: 46076 | B124: Quantum CSP | C124: meaksh | D124: Quantum-CSP
A125: 46076 | B125: PennyLaneAI (Lightning) | C125: PennyLaneAI | D125: pennylane-lightning | E125: 133 | F125: 50 | G125: 54 | H125: 30 | I125: 1 | J125: 5 | K125: 2 | L125: 11 | M125: 5
A126: 46076 | B126: SymPy | C126: sympy | D126: sympy | E126: 14407 | F126: 5093 | G126: 5564 | H126: 100 | I126: 24 | J126: 25 | K126: 65 | L126: 134 | M126: 3
A127: 46076 | B127: PyQIR | C127: qir-alliance | D127: pyqir | E127: 72 | F127: 30 | G127: 16 | H127: 1 | I127: 0 | J127: 0 | K127: 1 | L127: 0 | M127: 9
A128: 46076 | B128: Z2Pack | C128: physics-materials | D128: z2pack
A129: 46076 | B129: NetKet | C129: netket | D129: netket | E129: 665 | F129: 211 | G129: 108 | H129: 34 | I129: 6 | J129: 2 | K129: 0 | L129: 16 | M129: 13
A130: 46076 | B130: QuSpin | C130: weinbe58 | D130: QuSpin | E130: 32 | F130: 6 | G130: 0 | H130: 0 | I130: 0 | J130: 0 | K130: 0 | L130: 0 | M130: 0
A131: 46076 | B131: OpenQL | C131: QCG-OpenQL | D131: OpenQL
A132: 46076 | B132: Pymanopt | C132: pymanopt | D132: pymanopt | E132: 887 | F132: 163 | G132: 56 | H132: 11 | I132: 0 | J132: 0 | K132: 0 | L132: 0 | M132: 0
A133: 46076 | B133: Catalyst | C133: PennyLaneAI | D133: catalyst | E133: 200 | F133: 65 | G133: 245 | H133: 100 | I133: 16 | J133: 19 | K133: 6 | L133: 24 | M133: 5
A134: 46076 | B134: PyQIR | C134: qir-alliance | D134: qsharp-runtime
A135: 46076 | B135: Qiskit Nature | C135: qiskit-community | D135: qiskit-nature | E135: 372 | F135: 231 | G135: 69 | H135: 12 | I135: 0 | J135: 0 | K135: 0 | L135: 1 | M135: 0
A136: 46076 | B136: Qiskit Optimization | C136: qiskit-community | D136: qiskit-optimization | E136: 274 | F136: 146 | G136: 19 | H136: 2 | I136: 0 | J136: 0 | K136: 0 | L136: 0 | M136: 1
A137: 46076 | B137: Qiskit Machine Learning | C137: qiskit-community | D137: qiskit-machine-learning | E137: 945 | F137: 416 | G137: 27 | H137: 5 | I137: 1 | J137: 2 | K137: 6 | L137: 5 | M137: 3
A138: 46076 | B138: Qiskit Experiments | C138: qiskit-community | D138: qiskit-experiments | E138: 189 | F138: 131 | G138: 140 | H138: 31 | I138: 3 | J138: 1 | K138: 1 | L138: 1 | M138: 6
A139: 46076 | B139: Qiskit Aer | C139: qiskit-community | D139: qiskit-aer
A140: 46076 | B140: Qiskit Dynamics | C140: qiskit-community | D140: qiskit-dynamics | E140: 117 | F140: 62 | G140: 27 | H140: 8 | I140: 0 | J140: 0 | K140: 0 | L140: 0 | M140: 1
A141: 46076 | B141: Qiskit Transpiler | C141: qiskit-community | D141: qiskit-transpiler
A142: 46076 | B142: Qiskit Metal | C142: qiskit-community | D142: qiskit-metal | E142: 375 | F142: 249 | G142: 138 | H142: 8 | I142: 0 | J142: 0 | K142: 4 | L142: 3 | M142: 5
A143: 46076 | B143: Mitiq | C143: unitaryfund | D143: mitiq | E143: 416 | F143: 198 | G143: 99 | H143: 7 | I143: 6 | J143: 3 | K143: 11 | L143: 5 | M143: 7
A144: 46076 | B144: Qulacs | C144: qulacs | D144: qulacs | E144: 497 | F144: 135 | G144: 21 | H144: 2 | I144: 0 | J144: 2 | K144: 3 | L144: 4 | M144: 2
A145: 46076 | B145: Qulacs GPU | C145: qulacs | D145: qulacs-gpu
A146: 46076 | B146: Qsimcirq | C146: quantumlib | D146: qsim | E146: 641 | F146: 197 | G146: 53 | H146: 9 | I146: 0 | J146: 3 | K146: 3 | L146: 5 | M146: 1
A147: 46076 | B147: TensorNetwork Library | C147: google | D147: TensorNetwork | E147: 1866 | F147: 363 | G147: 131 | H147: 19 | I147: 0 | J147: 0 | K147: 0 | L147: 0 | M147: 0
A148: 46076 | B148: Quimb | C148: jcmgray | D148: quimb | E148: 608 | F148: 130 | G148: 76 | H148: 3 | I148: 8 | J148: 3 | K148: 0 | L148: 2 | M148: 5
...

Sheet PyPI_Snapshots
A1: Snapshot Date | B1: Company | C1: PyPI Package | D1: Downloads Last Day | E1: Downloads Last Week | F1: Downloads Last Month | G1: Full Last Month | H1: Prev Month | I1: -5 Months Ago | J1: -4 Months Ago2 | K1: -3 Months Ago | L1: -2 Months Ago
A2: 46059 | B2: Qiskit Community | C2: qiskit | D2: 29273 | E2: 186640 | F2: 838665
A3: 46059 | B3: AWS Braket | C3: amazon-braket-sdk | D3: 2487 | E3: 24992 | F3: 80341
A4: 46059 | B4: qBraid | C4: qbraid | D4: 468 | E4: 2750 | F4: 12112
A5: 46059 | B5: Aqora | C5: q3as | D5: 2 | E5: 4 | F5: 47
A6: 46059 | B6: Aqora | C6: aqora-cli | D6: 28 | E6: 1434 | F6: 4237
A7: 46064 | B7: Qiskit Community | C7: qiskit | D7: 35489 | E7: 185867 | F7: 842326
A8: 46064 | B8: AWS Braket | C8: amazon-braket-sdk | D8: 3582 | E8: 19818 | F8: 85718
A9: 46064 | B9: qBraid | C9: qbraid | D9: 785 | E9: 2946 | F9: 12511
A10: 46064 | B10: Aqora | C10: q3as | D10: 2 | E10: 7 | F10: 39
A11: 46064 | B11: Aqora | C11: aqora-cli | D11: 421 | E11: 3675 | F11: 6474
A12: 46064 | B12: Qiskit Community | C12: qiskit | D12: 35489 | E12: 185867 | F12: 842326
A13: 46064 | B13: AWS Braket | C13: amazon-braket-sdk | D13: 3582 | E13: 19818 | F13: 85718
... A16: 46064 | B16: Aqora | C16: aqora-cli | D16: 421 | E16: 3675 | F16: 6474
A17: 46065 | B17: Qiskit Community | C17: qiskit | D17: 33716 | E17: 190925 | F17: 842185 | G17: 10929 | H17: 37121
A18: 46065 | B18: AWS Braket | C18: amazon-braket-sdk
A19: 46065 | B19: qBraid | C19: qbraid | D19: 606 | E19: 3123 | F19: 12696 | G19: 116 | H19: 228
A20: 46065 | B20: Aqora | C20: q3as | D20: 4 | E20: 11 | F20: 42
A21: 46065 | B21: Aqora | C21: aqora-cli | D21: 544 | E21: 4194 | F21: 6970 | G21: 19 | H21: 29
A22: 46065 | B22: Aqora | C22: aqora-cli | D22: 544 | E22: 4194 | F22: 6970 | G22: 19 | H22: 29
A23: 46065 | B23: Qiskit Community | C23: qiskit | D23: 33716 | E23: 190925 | F23: 842185 | G23: 10929 | H23: 37121
A24: 46065 | B24: AWS Braket | C24: amazon-braket-sdk
A25: 46065 | B25: qBraid | C25: qbraid | D25: 606 | E25: 3123 | F25: 12696 | G25: 116 | H25: 228
A26: 46065 | B26: Aqora | C26: q3as | D26: 4 | E26: 11 | F26: 42
A27: 46065 | B27: Aqora | C27: aqora-cli | D27: 544 | E27: 4194 | F27: 6970 | G27: 19 | H27: 29
A28: 46065 | B28: Qiskit Community | C28: qiskit | D28: 33716 | E28: 190925 | F28: 842185 | G28: 796925 | H28: 835508
A29: 46065 | B29: AWS Braket | C29: amazon-braket-sdk | D29: 4778 | E29: 21928 | F29: 88078 | G29: 73130 | H29: 77395
A30: 46065 | B30: qBraid | C30: qbraid | D30: 606 | E30: 3123 | F30: 12696 | G30: 11141 | H30: 8779
A31: 46065 | B31: Aqora | C31: q3as | D31: 4 | E31: 11 | F31: 42 | G31: 44 | H31: 36
A32: 46065 | B32: Aqora | C32: aqora-cli | D32: 544 | E32: 4194 | F32: 6970 | G32: 4700 | H32: 1263
A33: 46065 | B33: Qiskit Community | C33: qiskit | D33: 33716 | E33: 190925 | F33: 842185 | G33: 796925 | H33: 835508
A34: 46065 | B34: AWS Braket | C34: amazon-braket-sdk | D34: 4778 | E34: 21928 | F34: 88078 | G34: 73130 | H34: 77395
A35: 46065 | B35: qBraid | C35: qbraid | D35: 606 | E35: 3123 | F35: 12696 | G35: 11141 | H35: 8779
A36: 46065 | B36: Aqora | C36: q3as | D36: 4 | E36: 11 | F36: 42 | G36: 44 | H36: 36
A37: 46065 | B37: Aqora | C37: aqora-cli | D37: 544 | E37: 4194 | F37: 6970 | G37: 4700 | H37: 1263
A38: 46065 | B38: Qiskit Community | C38: qiskit | D38: 33716 | E38: 190925 | F38: 842185 | G38: 796925 | H38: 835508
... A57: 46065 | B57: Aqora | C57: aqora-cli | D57: 544 | E57: 4194 | F57: 6970 | G57: 4700 | H57: 1263
A58: 46065 | B58: Qiskit Community | C58: qiskit | D58: 33716 | E58: 190925 | F58: 842185 | G58: 796925 | H58: 835508 | I58: 334573
A59: 46065 | B59: AWS Braket | C59: amazon-braket-sdk | D59: 4778 | E59: 21928 | F59: 88078 | G59: 73130 | H59: 77395 | I59: 54286
A60: 46065 | B60: qBraid | C60: qbraid | D60: 606 | E60: 3123 | F60: 12696 | G60: 11141 | H60: 8779 | I60: 5754
...

Sheet Trends_Snapshots
A1: Snapshot Date | B1: Company | C1: Trend Keyword | D1: Trends Index (0-100) | E1: Method | F1: Geo | G1: Timeframe | H1: Est Monthly Searches
A2: 46059 | B2: Qiskit Community | C2: qiskit | E2: weekly_avg | G2: today 12-m
A3: 46059 | B3: Qiskit Community | C3: qiskit | E3: weekly_avg | G3: today 12-m
A4: 46059 | B4: AWS Braket | C4: amazon braket | E4: weekly_avg | G4: today 12-m
A5: 46059 | B5: qBraid | C5: qbraid | E5: weekly_avg | G5: today 12-m
A6: 46059 | B6: Aqora | C6: aqora | E6: weekly_avg | G6: today 12-m
A7: 46059 | B7: Aqora | C7: aqora | E7: weekly_avg | G7: today 12-m
A8: 46064 | B8: Qiskit Community | C8: qiskit | D8: 38 | E8: weekly_avg | G8: today 12-m
A9: 46064 | B9: Qiskit Community | C9: qiskit | D9: 38 | E9: weekly_avg | G9: today 12-m
A10: 46064 | B10: AWS Braket | C10: amazon braket | D10: 2 | E10: weekly_avg | G10: today 12-m
A11: 46064 | B11: qBraid | C11: qbraid | D11: 0 | E11: weekly_avg | G11: today 12-m
A12: 46064 | B12: Aqora | C12: aqora | D12: 0 | E12: weekly_avg | G12: today 12-m
A13: 46064 | B13: Aqora | C13: aqora | D13: 0 | E13: weekly_avg | G13: today 12-m
A14: 46064 | B14: Qiskit Community | C14: qiskit | D14: 38 | E14: weekly_avg | G14: today 12-m
A15: 46064 | B15: Qiskit Community | C15: qiskit | D15: 38 | E15: weekly_avg | G15: today 12-m
A16: 46064 | B16: AWS Braket | C16: amazon braket | D16: 2 | E16: weekly_avg | G16: today 12-m
A17: 46064 | B17: qBraid | C17: qbraid | D17: 0 | E17: weekly_avg | G17: today 12-m
A18: 46064 | B18: Aqora | C18: aqora | D18: 0 | E18: weekly_avg | G18: today 12-m
A19: 46064 | B19: Aqora | C19: aqora | D19: 0 | E19: weekly_avg | G19: today 12-m
... A97: 46068 | B97: Aqora | C97: aqora | D97: 0 | E97: weekly_avg | G97: today 12-m
A98: 46076 | B98: Qiskit Community | C98: qiskit | E98: weekly_avg | G98: today 12-m
A99: 46076 | B99: Qiskit Community | C99: qiskit | E99: weekly_avg | G99: today 12-m
A100: 46076 | B100: AWS Braket | C100: amazon braket | E100: weekly_avg | G100: today 12-m
A101: 46076 | B101: qBraid | C101: qbraid | E101: weekly_avg | G101: today 12-m
A102: 46076 | B102: Aqora | C102: aqora | E102: weekly_avg | G102: today 12-m
A103: 46076 | B103: Aqora | C103: aqora | E103: weekly_avg | G103: today 12-m
A104: 46076 | B104: IBM | C104: qiskit | E104: weekly_avg | G104: today 12-m
A105: 46076 | B105: Google | C105: cirq | E105: weekly_avg | G105: today 12-m
A106: 46076 | B106: Xanadu | C106: pennylane | E106: weekly_avg | G106: today 12-m
A107: 46076 | B107: Amazon Braket | C107: amazon braket | E107: weekly_avg | G107: today 12-m
A108: 46076 | B108: D-Wave | C108: dwave ocean | E108: weekly_avg | G108: today 12-m
A109: 46076 | B109: Rigetti | C109: pyquil | E109: weekly_avg | G109: today 12-m
... A752: 46125 | B752: QGradients | C752: qgrad | E752: weekly_avg | G752: today 12-m

Sheet Graph Data
A1: Company | B1: PyPI Downloads (last month) | C1: PyPI Downloads (Prev Month) | D1: PyPI Downloads (Six Months Ago) | E1: PyPI Downloads (Five Months Ago) | F1: PyPI Downloads (Four Months Ago) | G1: PyPI Downloads (Three Months Ago) | H1: T-6 | I1: T-5 | J1: T-4 | K1: T-3 | L1: T-2 | M1: T-1
A2: {=IFERROR( _xlfn.LET( _xlpm.filtered, _xlfn.UNIQUE(_xlfn._xlws.FILTER(Config!$A$1:$A$498, Config!$G$1:$G$498="Y")), INDEX(_xlpm.filtered, ROW()-ROW($A$2)+1) ), "" )} | B2: {=_xlfn.LET( _xlpm.c,$A2, _xlpm.d,_xlfn.MAXIFS(PyPISnapshots[Snapshot Date],PyPISnapshots[Company],_xlpm.c), _xlpm.pkgs,_xlfn.UNIQUE(_xlfn._xlws.FILTER(PyPISnapshots[PyPI Package], (PyPISnapshots[Company]=_xlpm.c)*(PyPISnapshots[Snapshot Date]=_xlpm.d))), IFERROR( SUM( _xlfn.MAP(_xlpm.pkgs, _xlfn.LAMBDA(_xlpm.p, _xlfn.MAXIFS(PyPISnapshots[Downloads Last Month], PyPISnapshots[Company],_xlpm.c, PyPISnapshots[Snapshot Date],_xlpm.d, PyPISnapshots[PyPI Package],_xlpm.p) ))), "" ) )} | C2: {=_xlfn.LET( _xlpm.c,$A2, _xlpm.d,_xlfn.MAXIFS(PyPISnapshots[Snapshot Date],PyPISnapshots[Company],_xlpm.c), _xlpm.pkgs,_xlfn.UNIQUE(_xlfn._xlws.FILTER(PyPISnapshots[PyPI Package], (PyPISnapshots[Company]=_xlpm.c)*(PyPISnapshots[Snapshot Date]=_xlpm.d))), IFERROR( SUM( _xlfn.MAP(_xlpm.pkgs, _xlfn.LAMBDA(_xlpm.p, _xlfn.MAXIFS(PyPISnapshots[Prev Month], PyPISnapshots[Company],_xlpm.c, PyPISnapshots[Snapshot Date],_xlpm.d, PyPISnapshots[PyPI Package],_xlpm.p) ))), "" ) )} | D2: {=_xlfn.LET( _xlpm.c,$A2, _xlpm.d,_xlfn.MAXIFS(PyPISnapshots[Snapshot Date],PyPISnapshots[Company],_xlpm.c), _xlpm.pkgs,_xlfn.UNIQUE(_xlfn._xlws.FILTER(PyPISnapshots[PyPI Package], (PyPISnapshots[Company]=_xlpm.c)*(PyPISnapshots[Snapshot Date]=_xlpm.d))), IFERROR( SUM( _xlfn.MAP(_xlpm.pkgs, _xlfn.LAMBDA(_xlpm.p, _xlfn.MAXIFS(PyPISnapshots[-5 Months Ago], PyPISnapshots[Company],_xlpm.c, PyPISnapshots[Snapshot Date],_xlpm.d, PyPISnapshots[PyPI Package],_xlpm.p) ))), "" ) )} | E2: {=_xlfn.LET( _xlpm.c,$A2, _xlpm.d,_xlfn.MAXIFS(PyPISnapshots[Snapshot Date],PyPISnapshots[Company],_xlpm.c), _xlpm.pkgs,_xlfn.UNIQUE(_xlfn._xlws.FILTER(PyPISnapshots[PyPI Package], (PyPISnapshots[Company]=_xlpm.c)*(PyPISnapshots[Snapshot Date]=_xlpm.d))), IFERROR( SUM( _xlfn.MAP(_xlpm.pkgs, _xlfn.LAMBDA(_xlpm.p, _xlfn.MAXIFS(PyPISnapshots[-4 Months Ago2], PyPISnapshots[Company],_xlpm.c, PyPISnapshots[Snapshot Date],_xlpm.d, PyPISnapshots[PyPI Package],_xlpm.p) ))), "" ) )} | F2: {=_xlfn.LET( _xlpm.c,$A2, _xlpm.d,_xlfn.MAXIFS(PyPISnapshots[Snapshot Date],PyPISnapshots[Company],_xlpm.c), _xlpm.pkgs,_xlfn.UNIQUE(_xlfn._xlws.FILTER(PyPISnapshots[PyPI Package], (PyPISnapshots[Company]=_xlpm.c)*(PyPISnapshots[Snapshot Date]=_xlpm.d))), IFERROR( SUM( _xlfn.MAP(_xlpm.pkgs, _xlfn.LAMBDA(_xlpm.p, _xlfn.MAXIFS(PyPISnapshots[-3 Months Ago], PyPISnapshots[Company],_xlpm.c, PyPISnapshots[Snapshot Date],_xlpm.d, PyPISnapshots[PyPI Package],_xlpm.p) ))), "" ) )} | G2: {=_xlfn.LET( _xlpm.c,$A2, _xlpm.d,_xlfn.MAXIFS(PyPISnapshots[Snapshot Date],PyPISnapshots[Company],_xlpm.c), _xlpm.pkgs,_xlfn.UNIQUE(_xlfn._xlws.FILTER(PyPISnapshots[PyPI Package], (PyPISnapshots[Company]=_xlpm.c)*(PyPISnapshots[Snapshot Date]=_xlpm.d))), IFERROR( SUM( _xlfn.MAP(_xlpm.pkgs, _xlfn.LAMBDA(_xlpm.p, _xlfn.MAXIFS(PyPISnapshots[-2 Months Ago], PyPISnapshots[Company],_xlpm.c, PyPISnapshots[Snapshot Date],_xlpm.d, PyPISnapshots[PyPI Package],_xlpm.p) ))), "" ) )} | H2: =ProxyCalc7[[#This Row],[PyPI Downloads (Six Months Ago)]]/ProxyCalc7[[#This Row],[PyPI Downloads (Six Months Ago)]] | I2: =ProxyCalc7[[#This Row],[PyPI Downloads (Five Months Ago)]]/ProxyCalc7[[#This Row],[PyPI Downloads (Six Months Ago)]] | J2: =ProxyCalc7[[#This Row],[PyPI Downloads (Four Months Ago)]]/ProxyCalc7[[#This Row],[PyPI Downloads (Six Months Ago)]] | K2: =ProxyCalc7[[#This Row],[PyPI Downloads (Three Months Ago)]]/ProxyCalc7[[#This Row],[PyPI Downloads (Six Months Ago)]] | L2: =ProxyCalc7[[#This Row],[PyPI Downloads (Prev Month)]]/ProxyCalc7[[#This Row],[PyPI Downloads (Six Months Ago)]] | M2: =ProxyCalc7[[#This Row],[PyPI Downloads (last month)]]/ProxyCalc7[[#This Row],[PyPI Downloads (Six Months Ago)]]
A3: {=IFERROR( _xlfn.LET( _xlpm.filtered, _xlfn.UNIQUE(_xlfn._xlws.FILTER(Config!$A$1:$A$498, Config!$G$1:$G$498="Y")), INDEX(_xlpm.filtered, ROW()-ROW($A$2)+1) ), "" )} | B3: {=_xlfn.LET( _xlpm.c,$A3, _xlpm.d,_xlfn.MAXIFS(PyPISnapshots[Snapshot Date],PyPISnapshots[Company],_xlpm.c), _xlpm.pkgs,_xlfn.UNIQUE(_xlfn._xlws.FILTER(PyPISnapshots[PyPI Package], (PyPISnapshots[Company]=_xlpm.c)*(PyPISnapshots[Snapshot Date]=_xlpm.d))), IFERROR( SUM( _xlfn.MAP(_xlpm.pkgs, _xlfn.LAMBDA(_xlpm.p, _xlfn.MAXIFS(PyPISnapshots[Downloads Last Month], PyPISnapshots[Company],_xlpm.c, PyPISnapshots[Snapshot Date],_xlpm.d, PyPISnapshots[PyPI Package],_xlpm.p) ))), "" ) )} | C3: {=_xlfn.LET( _xlpm.c,$A3, _xlpm.d,_xlfn.MAXIFS(PyPISnapshots[Snapshot Date],PyPISnapshots[Company],_xlpm.c), _xlpm.pkgs,_xlfn.UNIQUE(_xlfn._xlws.FILTER(PyPISnapshots[PyPI Package], (PyPISnapshots[Company]=_xlpm.c)*(PyPISnapshots[Snapshot Date]=_xlpm.d))), IFERROR( SUM( _xlfn.MAP(_xlpm.pkgs, _xlfn.LAMBDA(_xlpm.p, _xlfn.MAXIFS(PyPISnapshots[Prev Month], PyPISnapshots[Company],_xlpm.c, PyPISnapshots[Snapshot Date],_xlpm.d, PyPISnapshots[PyPI Package],_xlpm.p) ))), "" ) )} | D3: {=_xlfn.LET( _xlpm.c,$A3, _xlpm.d,_xlfn.MAXIFS(PyPISnapshots[Snapshot Date],PyPISnapshots[Company],_xlpm.c), _xlpm.pkgs,_xlfn.UNIQUE(_xlfn._xlws.FILTER(PyPISnapshots[PyPI Package], (PyPISnapshots[Company]=_xlpm.c)*(PyPISnapshots[Snapshot Date]=_xlpm.d))), IFERROR( SUM( _xlfn.MAP(_xlpm.pkgs, _xlfn.LAMBDA(_xlpm.p, _xlfn.MAXIFS(PyPISnapshots[-5 Months Ago], PyPISnapshots[Company],_xlpm.c, PyPISnapshots[Snapshot Date],_xlpm.d, PyPISnapshots[PyPI Package],_xlpm.p) ))), "" ) )} | E3: {=_xlfn.LET( _xlpm.c,$A3, _xlpm.d,_xlfn.MAXIFS(PyPISnapshots[Snapshot Date],PyPISnapshots[Company],_xlpm.c), _xlpm.pkgs,_xlfn.UNIQUE(_xlfn._xlws.FILTER(PyPISnapshots[PyPI Package], (PyPISnapshots[Company]=_xlpm.c)*(PyPISnapshots[Snapshot Date]=_xlpm.d))), IFERROR( SUM( _xlfn.MAP(_xlpm.pkgs, _xlfn.LAMBDA(_xlpm.p, _xlfn.MAXIFS(PyPISnapshots[-4 Months Ago2], PyPISnapshots[Company],_xlpm.c, PyPISnapshots[Snapshot Date],_xlpm.d, PyPISnapshots[PyPI Package],_xlpm.p) ))), "" ) )} | F3: {=_xlfn.LET( _xlpm.c,$A3, _xlpm.d,_xlfn.MAXIFS(PyPISnapshots[Snapshot Date],PyPISnapshots[Company],_xlpm.c), _xlpm.pkgs,_xlfn.UNIQUE(_xlfn._xlws.FILTER(PyPISnapshots[PyPI Package], (PyPISnapshots[Company]=_xlpm.c)*(PyPISnapshots[Snapshot Date]=_xlpm.d))), IFERROR( SUM( _xlfn.MAP(_xlpm.pkgs, _xlfn.LAMBDA(_xlpm.p, _xlfn.MAXIFS(PyPISnapshots[-3 Months Ago], PyPISnapshots[Company],_xlpm.c, PyPISnapshots[Snapshot Date],_xlpm.d, PyPISnapshots[PyPI Package],_xlpm.p) ))), "" ) )} | G3: {=_xlfn.LET( _xlpm.c,$A3, _xlpm.d,_xlfn.MAXIFS(PyPISnapshots[Snapshot Date],PyPISnapshots[Company],_xlpm.c), _xlpm.pkgs,_xlfn.UNIQUE(_xlfn._xlws.FILTER(PyPISnapshots[PyPI Package], (PyPISnapshots[Company]=_xlpm.c)*(PyPISnapshots[Snapshot Date]=_xlpm.d))), IFERROR( SUM( _xlfn.MAP(_xlpm.pkgs, _xlfn.LAMBDA(_xlpm.p, _xlfn.MAXIFS(PyPISnapshots[-2 Months Ago], PyPISnapshots[Company],_xlpm.c, PyPISnapshots[Snapshot Date],_xlpm.d, PyPISnapshots[PyPI Package],_xlpm.p) ))), "" ) )} | H3: =ProxyCalc7[[#This Row],[PyPI Downloads (Six Months Ago)]]/ProxyCalc7[[#This Row],[PyPI Downloads (Six Months Ago)]] | I3: =ProxyCalc7[[#This Row],[PyPI Downloads (Five Months Ago)]]/ProxyCalc7[[#This Row],[PyPI Downloads (Six Months Ago)]] | J3: =ProxyCalc7[[#This Row],[PyPI Downloads (Four Months Ago)]]/ProxyCalc7[[#This Row],[PyPI Downloads (Six Months Ago)]] | K3: =ProxyCalc7[[#This Row],[PyPI Downloads (Three Months Ago)]]/ProxyCalc7[[#This Row],[PyPI Downloads (Six Months Ago)]] | L3: =ProxyCalc7[[#This Row],[PyPI Downloads (Prev Month)]]/ProxyCalc7[[#This Row],[PyPI Downloads (Six Months Ago)]] | M3: =ProxyCalc7[[#This Row],[PyPI Downloads (last month)]]/ProxyCalc7[[#This Row],[PyPI Downloads (Six Months Ago)]]
A4: {=IFERROR( _xlfn.LET( _xlpm.filtered, _xlfn.UNIQUE(_xlfn._xlws.FILTER(Config!$A$1:$A$498, Config!$G$1:$G$498="Y")), INDEX(_xlpm.filtered, ROW()-ROW($A$2)+1) ), "" )} | B4: {=_xlfn.LET( _xlpm.c,$A4, _xlpm.d,_xlfn.MAXIFS(PyPISnapshots[Snapshot Date],PyPISnapshots[Company],_xlpm.c), _xlpm.pkgs,_xlfn.UNIQUE(_xlfn._xlws.FILTER(PyPISnapshots[PyPI Package], (PyPISnapshots[Company]=_xlpm.c)*(PyPISnapshots[Snapshot Date]=_xlpm.d))), IFERROR( SUM( _xlfn.MAP(_xlpm.pkgs, _xlfn.LAMBDA(_xlpm.p, _xlfn.MAXIFS(PyPISnapshots[Downloads Last Month], PyPISnapshots[Company],_xlpm.c, PyPISnapshots[Snapshot Date],_xlpm.d, PyPISnapshots[PyPI Package],_xlpm.p) ))), "" ) )} | C4: {=_xlfn.LET( _xlpm.c,$A4, _xlpm.d,_xlfn.MAXIFS(PyPISnapshots[Snapshot Date],PyPISnapshots[Company],_xlpm.c), _xlpm.pkgs,_xlfn.UNIQUE(_xlfn._xlws.FILTER(PyPISnapshots[PyPI Package], (PyPISnapshots[Company]=_xlpm.c)*(PyPISnapshots[Snapshot Date]=_xlpm.d))), IFERROR( SUM( _xlfn.MAP(_xlpm.pkgs, _xlfn.LAMBDA(_xlpm.p, _xlfn.MAXIFS(PyPISnapshots[Prev Month], PyPISnapshots[Company],_xlpm.c, PyPISnapshots[Snapshot Date],_xlpm.d, PyPISnapshots[PyPI Package],_xlpm.p) ))), "" ) )} | D4: {=_xlfn.LET( _xlpm.c,$A4, _xlpm.d,_xlfn.MAXIFS(PyPISnapshots[Snapshot Date],PyPISnapshots[Company],_xlpm.c), _xlpm.pkgs,_xlfn.UNIQUE(_xlfn._xlws.FILTER(PyPISnapshots[PyPI Package], (PyPISnapshots[Company]=_xlpm.c)*(PyPISnapshots[Snapshot Date]=_xlpm.d))), IFERROR( SUM( _xlfn.MAP(_xlpm.pkgs, _xlfn.LAMBDA(_xlpm.p, _xlfn.MAXIFS(PyPISnapshots[-5 Months Ago], PyPISnapshots[Company],_xlpm.c, PyPISnapshots[Snapshot Date],_xlpm.d, PyPISnapshots[PyPI Package],_xlpm.p) ))), "" ) )} | E4: {=_xlfn.LET( _xlpm.c,$A4, _xlpm.d,_xlfn.MAXIFS(PyPISnapshots[Snapshot Date],PyPISnapshots[Company],_xlpm.c), _xlpm.pkgs,_xlfn.UNIQUE(_xlfn._xlws.FILTER(PyPISnapshots[PyPI Package], (PyPISnapshots[Company]=_xlpm.c)*(PyPISnapshots[Snapshot Date]=_xlpm.d))), IFERROR( SUM( _xlfn.MAP(_xlpm.pkgs, _xlfn.LAMBDA(_xlpm.p, _xlfn.MAXIFS(PyPISnapshots[-4 Months Ago2], PyPISnapshots[Company],_xlpm.c, PyPISnapshots[Snapshot Date],_xlpm.d, PyPISnapshots[PyPI Package],_xlpm.p) ))), "" ) )} | F4: {=_xlfn.LET( _xlpm.c,$A4, _xlpm.d,_xlfn.MAXIFS(PyPISnapshots[Snapshot Date],PyPISnapshots[Company],_xlpm.c), _xlpm.pkgs,_xlfn.UNIQUE(_xlfn._xlws.FILTER(PyPISnapshots[PyPI Package], (PyPISnapshots[Company]=_xlpm.c)*(PyPISnapshots[Snapshot Date]=_xlpm.d))), IFERROR( SUM( _xlfn.MAP(_xlpm.pkgs, _xlfn.LAMBDA(_xlpm.p, _xlfn.MAXIFS(PyPISnapshots[-3 Months Ago], PyPISnapshots[Company],_xlpm.c, PyPISnapshots[Snapshot Date],_xlpm.d, PyPISnapshots[PyPI Package],_xlpm.p) ))), "" ) )} | G4: {=_xlfn.LET( _xlpm.c,$A4, _xlpm.d,_xlfn.MAXIFS(PyPISnapshots[Snapshot Date],PyPISnapshots[Company],_xlpm.c), _xlpm.pkgs,_xlfn.UNIQUE(_xlfn._xlws.FILTER(PyPISnapshots[PyPI Package], (PyPISnapshots[Company]=_xlpm.c)*(PyPISnapshots[Snapshot Date]=_xlpm.d))), IFERROR( SUM( _xlfn.MAP(_xlpm.pkgs, _xlfn.LAMBDA(_xlpm.p, _xlfn.MAXIFS(PyPISnapshots[-2 Months Ago], PyPISnapshots[Company],_xlpm.c, PyPISnapshots[Snapshot Date],_xlpm.d, PyPISnapshots[PyPI Package],_xlpm.p) ))), "" ) )} | H4: =ProxyCalc7[[#This Row],[PyPI Downloads (Six Months Ago)]]/ProxyCalc7[[#This Row],[PyPI Downloads (Six Months Ago)]] | I4: =ProxyCalc7[[#This Row],[PyPI Downloads (Five Months Ago)]]/ProxyCalc7[[#This Row],[PyPI Downloads (Six Months Ago)]] | J4: =ProxyCalc7[[#This Row],[PyPI Downloads (Four Months Ago)]]/ProxyCalc7[[#This Row],[PyPI Downloads (Six Months Ago)]] | K4: =ProxyCalc7[[#This Row],[PyPI Downloads (Three Months Ago)]]/ProxyCalc7[[#This Row],[PyPI Downloads (Six Months Ago)]] | L4: =ProxyCalc7[[#This Row],[PyPI Downloads (Prev Month)]]/ProxyCalc7[[#This Row],[PyPI Downloads (Six Months Ago)]] | M4: =ProxyCalc7[[#This Row],[PyPI Downloads (last month)]]/ProxyCalc7[[#This Row],[PyPI Downloads (Six Months Ago)]]
A5: {=IFERROR( _xlfn.LET( _xlpm.filtered, _xlfn.UNIQUE(_xlfn._xlws.FILTER(Config!$A$1:$A$498, Config!$G$1:$G$498="Y")), INDEX(_xlpm.filtered, ROW()-ROW($A$2)+1) ), "" )} | B5: {=_xlfn.LET( _xlpm.c,$A5, _xlpm.d,_xlfn.MAXIFS(PyPISnapshots[Snapshot Date],PyPISnapshots[Company],_xlpm.c), _xlpm.pkgs,_xlfn.UNIQUE(_xlfn._xlws.FILTER(PyPISnapshots[PyPI Package], (PyPISnapshots[Company]=_xlpm.c)*(PyPISnapshots[Snapshot Date]=_xlpm.d))), IFERROR( SUM( _xlfn.MAP(_xlpm.pkgs, _xlfn.LAMBDA(_xlpm.p, _xlfn.MAXIFS(PyPISnapshots[Downloads Last Month], PyPISnapshots[Company],_xlpm.c, PyPISnapshots[Snapshot Date],_xlpm.d, PyPISnapshots[PyPI Package],_xlpm.p) ))), "" ) )} | C5: {=_xlfn.LET( _xlpm.c,$A5, _xlpm.d,_xlfn.MAXIFS(PyPISnapshots[Snapshot Date],PyPISnapshots[Company],_xlpm.c), _xlpm.pkgs,_xlfn.UNIQUE(_xlfn._xlws.FILTER(PyPISnapshots[PyPI Package], (PyPISnapshots[Company]=_xlpm.c)*(PyPISnapshots[Snapshot Date]=_xlpm.d))), IFERROR( SUM( _xlfn.MAP(_xlpm.pkgs, _xlfn.LAMBDA(_xlpm.p, _xlfn.MAXIFS(PyPISnapshots[Prev Month], PyPISnapshots[Company],_xlpm.c, PyPISnapshots[Snapshot Date],_xlpm.d, PyPISnapshots[PyPI Package],_xlpm.p) ))), "" ) )} | D5: {=_xlfn.LET( _xlpm.c,$A5, _xlpm.d,_xlfn.MAXIFS(PyPISnapshots[Snapshot Date],PyPISnapshots[Company],_xlpm.c), _xlpm.pkgs,_xlfn.UNIQUE(_xlfn._xlws.FILTER(PyPISnapshots[PyPI Package], (PyPISnapshots[Company]=_xlpm.c)*(PyPISnapshots[Snapshot Date]=_xlpm.d))), IFERROR( SUM( _xlfn.MAP(_xlpm.pkgs, _xlfn.LAMBDA(_xlpm.p, _xlfn.MAXIFS(PyPISnapshots[-5 Months Ago], PyPISnapshots[Company],_xlpm.c, PyPISnapshots[Snapshot Date],_xlpm.d, PyPISnapshots[PyPI Package],_xlpm.p) ))), "" ) )} | E5: {=_xlfn.LET( _xlpm.c,$A5, _xlpm.d,_xlfn.MAXIFS(PyPISnapshots[Snapshot Date],PyPISnapshots[Company],_xlpm.c), _xlpm.pkgs,_xlfn.UNIQUE(_xlfn._xlws.FILTER(PyPISnapshots[PyPI Package], (PyPISnapshots[Company]=_xlpm.c)*(PyPISnapshots[Snapshot Date]=_xlpm.d))), IFERROR( SUM( _xlfn.MAP(_xlpm.pkgs, _xlfn.LAMBDA(_xlpm.p, _xlfn.MAXIFS(PyPISnapshots[-4 Months Ago2], PyPISnapshots[Company],_xlpm.c, PyPISnapshots[Snapshot Date],_xlpm.d, PyPISnapshots[PyPI Package],_xlpm.p) ))), "" ) )} | F5: {=_xlfn.LET( _xlpm.c,$A5, _xlpm.d,_xlfn.MAXIFS(PyPISnapshots[Snapshot Date],PyPISnapshots[Company],_xlpm.c), _xlpm.pkgs,_xlfn.UNIQUE(_xlfn._xlws.FILTER(PyPISnapshots[PyPI Package], (PyPISnapshots[Company]=_xlpm.c)*(PyPISnapshots[Snapshot Date]=_xlpm.d))), IFERROR( SUM( _xlfn.MAP(_xlpm.pkgs, _xlfn.LAMBDA(_xlpm.p, _xlfn.MAXIFS(PyPISnapshots[-3 Months Ago], PyPISnapshots[Company],_xlpm.c, PyPISnapshots[Snapshot Date],_xlpm.d, PyPISnapshots[PyPI Package],_xlpm.p) ))), "" ) )} | G5: {=_xlfn.LET( _xlpm.c,$A5, _xlpm.d,_xlfn.MAXIFS(PyPISnapshots[Snapshot Date],PyPISnapshots[Company],_xlpm.c), _xlpm.pkgs,_xlfn.UNIQUE(_xlfn._xlws.FILTER(PyPISnapshots[PyPI Package], (PyPISnapshots[Company]=_xlpm.c)*(PyPISnapshots[Snapshot Date]=_xlpm.d))), IFERROR( SUM( _xlfn.MAP(_xlpm.pkgs, _xlfn.LAMBDA(_xlpm.p, _xlfn.MAXIFS(PyPISnapshots[-2 Months Ago], PyPISnapshots[Company],_xlpm.c, PyPISnapshots[Snapshot Date],_xlpm.d, PyPISnapshots[PyPI Package],_xlpm.p) ))), "" ) )} | H5: =ProxyCalc7[[#This Row],[PyPI Downloads (Six Months Ago)]]/ProxyCalc7[[#This Row],[PyPI Downloads (Six Months Ago)]] | I5: =ProxyCalc7[[#This Row],[PyPI Downloads (Five Months Ago)]]/ProxyCalc7[[#This Row],[PyPI Downloads (Six Months Ago)]] | J5: =ProxyCalc7[[#This Row],[PyPI Downloads (Four Months Ago)]]/ProxyCalc7[[#This Row],[PyPI Downloads (Six Months Ago)]] | K5: =ProxyCalc7[[#This Row],[PyPI Downloads (Three Months Ago)]]/ProxyCalc7[[#This Row],[PyPI Downloads (Six Months Ago)]] | L5: =ProxyCalc7[[#This Row],[PyPI Downloads (Prev Month)]]/ProxyCalc7[[#This Row],[PyPI Downloads (Six Months Ago)]] | M5: =ProxyCalc7[[#This Row],[PyPI Downloads (last month)]]/ProxyCalc7[[#This Row],[PyPI Downloads (Six Months Ago)]]
A6: {=IFERROR( _xlfn.LET( _xlpm.filtered, _xlfn.UNIQUE(_xlfn._xlws.FILTER(Config!$A$1:$A$498, Config!$G$1:$G$498="Y")), INDEX(_xlpm.filtered, ROW()-ROW($A$2)+1) ), "" )} | B6: {=_xlfn.LET( _xlpm.c,$A6, _xlpm.d,_xlfn.MAXIFS(PyPISnapshots[Snapshot Date],PyPISnapshots[Company],_xlpm.c), _xlpm.pkgs,_xlfn.UNIQUE(_xlfn._xlws.FILTER(PyPISnapshots[PyPI Package], (PyPISnapshots[Company]=_xlpm.c)*(PyPISnapshots[Snapshot Date]=_xlpm.d))), IFERROR( SUM( _xlfn.MAP(_xlpm.pkgs, _xlfn.LAMBDA(_xlpm.p, _xlfn.MAXIFS(PyPISnapshots[Downloads Last Month], PyPISnapshots[Company],_xlpm.c, PyPISnapshots[Snapshot Date],_xlpm.d, PyPISnapshots[PyPI Package],_xlpm.p) ))), "" ) )} | C6: {=_xlfn.LET( _xlpm.c,$A6, _xlpm.d,_xlfn.MAXIFS(PyPISnapshots[Snapshot Date],PyPISnapshots[Company],_xlpm.c), _xlpm.pkgs,_xlfn.UNIQUE(_xlfn._xlws.FILTER(PyPISnapshots[PyPI Package], (PyPISnapshots[Company]=_xlpm.c)*(PyPISnapshots[Snapshot Date]=_xlpm.d))), IFERROR( SUM( _xlfn.MAP(_xlpm.pkgs, _xlfn.LAMBDA(_xlpm.p, _xlfn.MAXIFS(PyPISnapshots[Prev Month], PyPISnapshots[Company],_xlpm.c, PyPISnapshots[Snapshot Date],_xlpm.d, PyPISnapshots[PyPI Package],_xlpm.p) ))), "" ) )} | D6: {=_xlfn.LET( _xlpm.c,$A6, _xlpm.d,_xlfn.MAXIFS(PyPISnapshots[Snapshot Date],PyPISnapshots[Company],_xlpm.c), _xlpm.pkgs,_xlfn.UNIQUE(_xlfn._xlws.FILTER(PyPISnapshots[PyPI Package], (PyPISnapshots[Company]=_xlpm.c)*(PyPISnapshots[Snapshot Date]=_xlpm.d))), IFERROR( SUM( _xlfn.MAP(_xlpm.pkgs, _xlfn.LAMBDA(_xlpm.p, _xlfn.MAXIFS(PyPISnapshots[-5 Months Ago], PyPISnapshots[Company],_xlpm.c, PyPISnapshots[Snapshot Date],_xlpm.d, PyPISnapshots[PyPI Package],_xlpm.p) ))), "" ) )} | E6: {=_xlfn.LET( _xlpm.c,$A6, _xlpm.d,_xlfn.MAXIFS(PyPISnapshots[Snapshot Date],PyPISnapshots[Company],_xlpm.c), _xlpm.pkgs,_xlfn.UNIQUE(_xlfn._xlws.FILTER(PyPISnapshots[PyPI Package], (PyPISnapshots[Company]=_xlpm.c)*(PyPISnapshots[Snapshot Date]=_xlpm.d))), IFERROR( SUM( _xlfn.MAP(_xlpm.pkgs, _xlfn.LAMBDA(_xlpm.p, _xlfn.MAXIFS(PyPISnapshots[-4 Months Ago2], PyPISnapshots[Company],_xlpm.c, PyPISnapshots[Snapshot Date],_xlpm.d, PyPISnapshots[PyPI Package],_xlpm.p) ))), "" ) )} | F6: {=_xlfn.LET( _xlpm.c,$A6, _xlpm.d,_xlfn.MAXIFS(PyPISnapshots[Snapshot Date],PyPISnapshots[Company],_xlpm.c), _xlpm.pkgs,_xlfn.UNIQUE(_xlfn._xlws.FILTER(PyPISnapshots[PyPI Package], (PyPISnapshots[Company]=_xlpm.c)*(PyPISnapshots[Snapshot Date]=_xlpm.d))), IFERROR( SUM( _xlfn.MAP(_xlpm.pkgs, _xlfn.LAMBDA(_xlpm.p, _xlfn.MAXIFS(PyPISnapshots[-3 Months Ago], PyPISnapshots[Company],_xlpm.c, PyPISnapshots[Snapshot Date],_xlpm.d, PyPISnapshots[PyPI Package],_xlpm.p) ))), "" ) )} | G6: {=_xlfn.LET( _xlpm.c,$A6, _xlpm.d,_xlfn.MAXIFS(PyPISnapshots[Snapshot Date],PyPISnapshots[Company],_xlpm.c), _xlpm.pkgs,_xlfn.UNIQUE(_xlfn._xlws.FILTER(PyPISnapshots[PyPI Package], (PyPISnapshots[Company]=_xlpm.c)*(PyPISnapshots[Snapshot Date]=_xlpm.d))), IFERROR( SUM( _xlfn.MAP(_xlpm.pkgs, _xlfn.LAMBDA(_xlpm.p, _xlfn.MAXIFS(PyPISnapshots[-2 Months Ago], PyPISnapshots[Company],_xlpm.c, PyPISnapshots[Snapshot Date],_xlpm.d, PyPISnapshots[PyPI Package],_xlpm.p) ))), "" ) )} | H6: =ProxyCalc7[[#This Row],[PyPI Downloads (Six Months Ago)]]/ProxyCalc7[[#This Row],[PyPI Downloads (Six Months Ago)]] | I6: =ProxyCalc7[[#This Row],[PyPI Downloads (Five Months Ago)]]/ProxyCalc7[[#This Row],[PyPI Downloads (Six Months Ago)]] | J6: =ProxyCalc7[[#This Row],[PyPI Downloads (Four Months Ago)]]/ProxyCalc7[[#This Row],[PyPI Downloads (Six Months Ago)]] | K6: =ProxyCalc7[[#This Row],[PyPI Downloads (Three Months Ago)]]/ProxyCalc7[[#This Row],[PyPI Downloads (Six Months Ago)]] | L6: =ProxyCalc7[[#This Row],[PyPI Downloads (Prev Month)]]/ProxyCalc7[[#This Row],[PyPI Downloads (Six Months Ago)]] | M6: =ProxyCalc7[[#This Row],[PyPI Downloads (last month)]]/ProxyCalc7[[#This Row],[PyPI Downloads (Six Months Ago)]]
A7: {=IFERROR( _xlfn.LET( _xlpm.filtered, _xlfn.UNIQUE(_xlfn._xlws.FILTER(Config!$A$1:$A$498, Config!$G$1:$G$498="Y")), INDEX(_xlpm.filtered, ROW()-ROW($A$2)+1) ), "" )} | B7: {=_xlfn.LET( _xlpm.c,$A7, _xlpm.d,_xlfn.MAXIFS(PyPISnapshots[Snapshot Date],PyPISnapshots[Company],_xlpm.c), _xlpm.pkgs,_xlfn.UNIQUE(_xlfn._xlws.FILTER(PyPISnapshots[PyPI Package], (PyPISnapshots[Company]=_xlpm.c)*(PyPISnapshots[Snapshot Date]=_xlpm.d))), IFERROR( SUM( _xlfn.MAP(_xlpm.pkgs, _xlfn.LAMBDA(_xlpm.p, _xlfn.MAXIFS(PyPISnapshots[Downloads Last Month], PyPISnapshots[Company],_xlpm.c, PyPISnapshots[Snapshot Date],_xlpm.d, PyPISnapshots[PyPI Package],_xlpm.p) ))), "" ) )} | C7: {=_xlfn.LET( _xlpm.c,$A7, _xlpm.d,_xlfn.MAXIFS(PyPISnapshots[Snapshot Date],PyPISnapshots[Company],_xlpm.c), _xlpm.pkgs,_xlfn.UNIQUE(_xlfn._xlws.FILTER(PyPISnapshots[PyPI Package], (PyPISnapshots[Company]=_xlpm.c)*(PyPISnapshots[Snapshot Date]=_xlpm.d))), IFERROR( SUM( _xlfn.MAP(_xlpm.pkgs, _xlfn.LAMBDA(_xlpm.p, _xlfn.MAXIFS(PyPISnapshots[Prev Month], PyPISnapshots[Company],_xlpm.c, PyPISnapshots[Snapshot Date],_xlpm.d, PyPISnapshots[PyPI Package],_xlpm.p) ))), "" ) )} | D7: {=_xlfn.LET( _xlpm.c,$A7, _xlpm.d,_xlfn.MAXIFS(PyPISnapshots[Snapshot Date],PyPISnapshots[Company],_xlpm.c), _xlpm.pkgs,_xlfn.UNIQUE(_xlfn._xlws.FILTER(PyPISnapshots[PyPI Package], (PyPISnapshots[Company]=_xlpm.c)*(PyPISnapshots[Snapshot Date]=_xlpm.d))), IFERROR( SUM( _xlfn.MAP(_xlpm.pkgs, _xlfn.LAMBDA(_xlpm.p, _xlfn.MAXIFS(PyPISnapshots[-5 Months Ago], PyPISnapshots[Company],_xlpm.c, PyPISnapshots[Snapshot Date],_xlpm.d, PyPISnapshots[PyPI Package],_xlpm.p) ))), "" ) )} | E7: {=_xlfn.LET( _xlpm.c,$A7, _xlpm.d,_xlfn.MAXIFS(PyPISnapshots[Snapshot Date],PyPISnapshots[Company],_xlpm.c), _xlpm.pkgs,_xlfn.UNIQUE(_xlfn._xlws.FILTER(PyPISnapshots[PyPI Package], (PyPISnapshots[Company]=_xlpm.c)*(PyPISnapshots[Snapshot Date]=_xlpm.d))), IFERROR( SUM( _xlfn.MAP(_xlpm.pkgs, _xlfn.LAMBDA(_xlpm.p, _xlfn.MAXIFS(PyPISnapshots[-4 Months Ago2], PyPISnapshots[Company],_xlpm.c, PyPISnapshots[Snapshot Date],_xlpm.d, PyPISnapshots[PyPI Package],_xlpm.p) ))), "" ) )} | F7: {=_xlfn.LET( _xlpm.c,$A7, _xlpm.d,_xlfn.MAXIFS(PyPISnapshots[Snapshot Date],PyPISnapshots[Company],_xlpm.c), _xlpm.pkgs,_xlfn.UNIQUE(_xlfn._xlws.FILTER(PyPISnapshots[PyPI Package], (PyPISnapshots[Company]=_xlpm.c)*(PyPISnapshots[Snapshot Date]=_xlpm.d))), IFERROR( SUM( _xlfn.MAP(_xlpm.pkgs, _xlfn.LAMBDA(_xlpm.p, _xlfn.MAXIFS(PyPISnapshots[-3 Months Ago], PyPISnapshots[Company],_xlpm.c, PyPISnapshots[Snapshot Date],_xlpm.d, PyPISnapshots[PyPI Package],_xlpm.p) ))), "" ) )} | G7: {=_xlfn.LET( _xlpm.c,$A7, _xlpm.d,_xlfn.MAXIFS(PyPISnapshots[Snapshot Date],PyPISnapshots[Company],_xlpm.c), _xlpm.pkgs,_xlfn.UNIQUE(_xlfn._xlws.FILTER(PyPISnapshots[PyPI Package], (PyPISnapshots[Company]=_xlpm.c)*(PyPISnapshots[Snapshot Date]=_xlpm.d))), IFERROR( SUM( _xlfn.MAP(_xlpm.pkgs, _xlfn.LAMBDA(_xlpm.p, _xlfn.MAXIFS(PyPISnapshots[-2 Months Ago], PyPISnapshots[Company],_xlpm.c, PyPISnapshots[Snapshot Date],_xlpm.d, PyPISnapshots[PyPI Package],_xlpm.p) ))), "" ) )} | H7: =ProxyCalc7[[#This Row],[PyPI Downloads (Six Months Ago)]]/ProxyCalc7[[#This Row],[PyPI Downloads (Six Months Ago)]] | I7: =ProxyCalc7[[#This Row],[PyPI Downloads (Five Months Ago)]]/ProxyCalc7[[#This Row],[PyPI Downloads (Six Months Ago)]] | J7: =ProxyCalc7[[#This Row],[PyPI Downloads (Four Months Ago)]]/ProxyCalc7[[#This Row],[PyPI Downloads (Six Months Ago)]] | K7: =ProxyCalc7[[#This Row],[PyPI Downloads (Three Months Ago)]]/ProxyCalc7[[#This Row],[PyPI Downloads (Six Months Ago)]] | L7: =ProxyCalc7[[#This Row],[PyPI Downloads (Prev Month)]]/ProxyCalc7[[#This Row],[PyPI Downloads (Six Months Ago)]] | M7: =ProxyCalc7[[#This Row],[PyPI Downloads (last month)]]/ProxyCalc7[[#This Row],[PyPI Downloads (Six Months Ago)]]
A8: {=IFERROR( _xlfn.LET( _xlpm.filtered, _xlfn.UNIQUE(_xlfn._xlws.FILTER(Config!$A$1:$A$498, Config!$G$1:$G$498="Y")), INDEX(_xlpm.filtered, ROW()-ROW($A$2)+1) ), "" )} | B8: {=_xlfn.LET( _xlpm.c,$A8, _xlpm.d,_xlfn.MAXIFS(PyPISnapshots[Snapshot Date],PyPISnapshots[Company],_xlpm.c), _xlpm.pkgs,_xlfn.UNIQUE(_xlfn._xlws.FILTER(PyPISnapshots[PyPI Package], (PyPISnapshots[Company]=_xlpm.c)*(PyPISnapshots[Snapshot Date]=_xlpm.d))), IFERROR( SUM( _xlfn.MAP(_xlpm.pkgs, _xlfn.LAMBDA(_xlpm.p, _xlfn.MAXIFS(PyPISnapshots[Downloads Last Month], PyPISnapshots[Company],_xlpm.c, PyPISnapshots[Snapshot Date],_xlpm.d, PyPISnapshots[PyPI Package],_xlpm.p) ))), "" ) )} | C8: {=_xlfn.LET( _xlpm.c,$A8, _xlpm.d,_xlfn.MAXIFS(PyPISnapshots[Snapshot Date],PyPISnapshots[Company],_xlpm.c), _xlpm.pkgs,_xlfn.UNIQUE(_xlfn._xlws.FILTER(PyPISnapshots[PyPI Package], (PyPISnapshots[Company]=_xlpm.c)*(PyPISnapshots[Snapshot Date]=_xlpm.d))), IFERROR( SUM( _xlfn.MAP(_xlpm.pkgs, _xlfn.LAMBDA(_xlpm.p, _xlfn.MAXIFS(PyPISnapshots[Prev Month], PyPISnapshots[Company],_xlpm.c, PyPISnapshots[Snapshot Date],_xlpm.d, PyPISnapshots[PyPI Package],_xlpm.p) ))), "" ) )} | D8: {=_xlfn.LET( _xlpm.c,$A8, _xlpm.d,_xlfn.MAXIFS(PyPISnapshots[Snapshot Date],PyPISnapshots[Company],_xlpm.c), _xlpm.pkgs,_xlfn.UNIQUE(_xlfn._xlws.FILTER(PyPISnapshots[PyPI Package], (PyPISnapshots[Company]=_xlpm.c)*(PyPISnapshots[Snapshot Date]=_xlpm.d))), IFERROR( SUM( _xlfn.MAP(_xlpm.pkgs, _xlfn.LAMBDA(_xlpm.p, _xlfn.MAXIFS(PyPISnapshots[-5 Months Ago], PyPISnapshots[Company],_xlpm.c, PyPISnapshots[Snapshot Date],_xlpm.d, PyPISnapshots[PyPI Package],_xlpm.p) ))), "" ) )} | E8: {=_xlfn.LET( _xlpm.c,$A8, _xlpm.d,_xlfn.MAXIFS(PyPISnapshots[Snapshot Date],PyPISnapshots[Company],_xlpm.c), _xlpm.pkgs,_xlfn.UNIQUE(_xlfn._xlws.FILTER(PyPISnapshots[PyPI Package], (PyPISnapshots[Company]=_xlpm.c)*(PyPISnapshots[Snapshot Date]=_xlpm.d))), IFERROR( SUM( _xlfn.MAP(_xlpm.pkgs, _xlfn.LAMBDA(_xlpm.p, _xlfn.MAXIFS(PyPISnapshots[-4 Months Ago2], PyPISnapshots[Company],_xlpm.c, PyPISnapshots[Snapshot Date],_xlpm.d, PyPISnapshots[PyPI Package],_xlpm.p) ))), "" ) )} | F8: {=_xlfn.LET( _xlpm.c,$A8, _xlpm.d,_xlfn.MAXIFS(PyPISnapshots[Snapshot Date],PyPISnapshots[Company],_xlpm.c), _xlpm.pkgs,_xlfn.UNIQUE(_xlfn._xlws.FILTER(PyPISnapshots[PyPI Package], (PyPISnapshots[Company]=_xlpm.c)*(PyPISnapshots[Snapshot Date]=_xlpm.d))), IFERROR( SUM( _xlfn.MAP(_xlpm.pkgs, _xlfn.LAMBDA(_xlpm.p, _xlfn.MAXIFS(PyPISnapshots[-3 Months Ago], PyPISnapshots[Company],_xlpm.c, PyPISnapshots[Snapshot Date],_xlpm.d, PyPISnapshots[PyPI Package],_xlpm.p) ))), "" ) )} | G8: {=_xlfn.LET( _xlpm.c,$A8, _xlpm.d,_xlfn.MAXIFS(PyPISnapshots[Snapshot Date],PyPISnapshots[Company],_xlpm.c), _xlpm.pkgs,_xlfn.UNIQUE(_xlfn._xlws.FILTER(PyPISnapshots[PyPI Package], (PyPISnapshots[Company]=_xlpm.c)*(PyPISnapshots[Snapshot Date]=_xlpm.d))), IFERROR( SUM( _xlfn.MAP(_xlpm.pkgs, _xlfn.LAMBDA(_xlpm.p, _xlfn.MAXIFS(PyPISnapshots[-2 Months Ago], PyPISnapshots[Company],_xlpm.c, PyPISnapshots[Snapshot Date],_xlpm.d, PyPISnapshots[PyPI Package],_xlpm.p) ))), "" ) )} | H8: =ProxyCalc7[[#This Row],[PyPI Downloads (Six Months Ago)]]/ProxyCalc7[[#This Row],[PyPI Downloads (Six Months Ago)]] | I8: =ProxyCalc7[[#This Row],[PyPI Downloads (Five Months Ago)]]/ProxyCalc7[[#This Row],[PyPI Downloads (Six Months Ago)]] | J8: =ProxyCalc7[[#This Row],[PyPI Downloads (Four Months Ago)]]/ProxyCalc7[[#This Row],[PyPI Downloads (Six Months Ago)]] | K8: =ProxyCalc7[[#This Row],[PyPI Downloads (Three Months Ago)]]/ProxyCalc7[[#This Row],[PyPI Downloads (Six Months Ago)]] | L8: =ProxyCalc7[[#This Row],[PyPI Downloads (Prev Month)]]/ProxyCalc7[[#This Row],[PyPI Downloads (Six Months Ago)]] | M8: =ProxyCalc7[[#This Row],[PyPI Downloads (last month)]]/ProxyCalc7[[#This Row],[PyPI Downloads (Six Months Ago)]]
A9: {=IFERROR( _xlfn.LET( _xlpm.filtered, _xlfn.UNIQUE(_xlfn._xlws.FILTER(Config!$A$1:$A$498, Config!$G$1:$G$498="Y")), INDEX(_xlpm.filtered, ROW()-ROW($A$2)+1) ), "" )} | B9: {=_xlfn.LET( _xlpm.c,$A9, _xlpm.d,_xlfn.MAXIFS(PyPISnapshots[Snapshot Date],PyPISnapshots[Company],_xlpm.c), _xlpm.pkgs,_xlfn.UNIQUE(_xlfn._xlws.FILTER(PyPISnapshots[PyPI Package], (PyPISnapshots[Company]=_xlpm.c)*(PyPISnapshots[Snapshot Date]=_xlpm.d))), IFERROR( SUM( _xlfn.MAP(_xlpm.pkgs, _xlfn.LAMBDA(_xlpm.p, _xlfn.MAXIFS(PyPISnapshots[Downloads Last Month], PyPISnapshots[Company],_xlpm.c, PyPISnapshots[Snapshot Date],_xlpm.d, PyPISnapshots[PyPI Package],_xlpm.p) ))), "" ) )} | C9: {=_xlfn.LET( _xlpm.c,$A9, _xlpm.d,_xlfn.MAXIFS(PyPISnapshots[Snapshot Date],PyPISnapshots[Company],_xlpm.c), _xlpm.pkgs,_xlfn.UNIQUE(_xlfn._xlws.FILTER(PyPISnapshots[PyPI Package], (PyPISnapshots[Company]=_xlpm.c)*(PyPISnapshots[Snapshot Date]=_xlpm.d))), IFERROR( SUM( _xlfn.MAP(_xlpm.pkgs, _xlfn.LAMBDA(_xlpm.p, _xlfn.MAXIFS(PyPISnapshots[Prev Month], PyPISnapshots[Company],_xlpm.c, PyPISnapshots[Snapshot Date],_xlpm.d, PyPISnapshots[PyPI Package],_xlpm.p) ))), "" ) )} | D9: {=_xlfn.LET( _xlpm.c,$A9, _xlpm.d,_xlfn.MAXIFS(PyPISnapshots[Snapshot Date],PyPISnapshots[Company],_xlpm.c), _xlpm.pkgs,_xlfn.UNIQUE(_xlfn._xlws.FILTER(PyPISnapshots[PyPI Package], (PyPISnapshots[Company]=_xlpm.c)*(PyPISnapshots[Snapshot Date]=_xlpm.d))), IFERROR( SUM( _xlfn.MAP(_xlpm.pkgs, _xlfn.LAMBDA(_xlpm.p, _xlfn.MAXIFS(PyPISnapshots[-5 Months Ago], PyPISnapshots[Company],_xlpm.c, PyPISnapshots[Snapshot Date],_xlpm.d, PyPISnapshots[PyPI Package],_xlpm.p) ))), "" ) )} | E9: {=_xlfn.LET( _xlpm.c,$A9, _xlpm.d,_xlfn.MAXIFS(PyPISnapshots[Snapshot Date],PyPISnapshots[Company],_xlpm.c), _xlpm.pkgs,_xlfn.UNIQUE(_xlfn._xlws.FILTER(PyPISnapshots[PyPI Package], (PyPISnapshots[Company]=_xlpm.c)*(PyPISnapshots[Snapshot Date]=_xlpm.d))), IFERROR( SUM( _xlfn.MAP(_xlpm.pkgs, _xlfn.LAMBDA(_xlpm.p, _xlfn.MAXIFS(PyPISnapshots[-4 Months Ago2], PyPISnapshots[Company],_xlpm.c, PyPISnapshots[Snapshot Date],_xlpm.d, PyPISnapshots[PyPI Package],_xlpm.p) ))), "" ) )} | F9: {=_xlfn.LET( _xlpm.c,$A9, _xlpm.d,_xlfn.MAXIFS(PyPISnapshots[Snapshot Date],PyPISnapshots[Company],_xlpm.c), _xlpm.pkgs,_xlfn.UNIQUE(_xlfn._xlws.FILTER(PyPISnapshots[PyPI Package], (PyPISnapshots[Company]=_xlpm.c)*(PyPISnapshots[Snapshot Date]=_xlpm.d))), IFERROR( SUM( _xlfn.MAP(_xlpm.pkgs, _xlfn.LAMBDA(_xlpm.p, _xlfn.MAXIFS(PyPISnapshots[-3 Months Ago], PyPISnapshots[Company],_xlpm.c, PyPISnapshots[Snapshot Date],_xlpm.d, PyPISnapshots[PyPI Package],_xlpm.p) ))), "" ) )} | G9: {=_xlfn.LET( _xlpm.c,$A9, _xlpm.d,_xlfn.MAXIFS(PyPISnapshots[Snapshot Date],PyPISnapshots[Company],_xlpm.c), _xlpm.pkgs,_xlfn.UNIQUE(_xlfn._xlws.FILTER(PyPISnapshots[PyPI Package], (PyPISnapshots[Company]=_xlpm.c)*(PyPISnapshots[Snapshot Date]=_xlpm.d))), IFERROR( SUM( _xlfn.MAP(_xlpm.pkgs, _xlfn.LAMBDA(_xlpm.p, _xlfn.MAXIFS(PyPISnapshots[-2 Months Ago], PyPISnapshots[Company],_xlpm.c, PyPISnapshots[Snapshot Date],_xlpm.d, PyPISnapshots[PyPI Package],_xlpm.p) ))), "" ) )} | H9: =ProxyCalc7[[#This Row],[PyPI Downloads (Six Months Ago)]]/ProxyCalc7[[#This Row],[PyPI Downloads (Six Months Ago)]] | I9: =ProxyCalc7[[#This Row],[PyPI Downloads (Five Months Ago)]]/ProxyCalc7[[#This Row],[PyPI Downloads (Six Months Ago)]] | J9: =ProxyCalc7[[#This Row],[PyPI Downloads (Four Months Ago)]]/ProxyCalc7[[#This Row],[PyPI Downloads (Six Months Ago)]] | K9: =ProxyCalc7[[#This Row],[PyPI Downloads (Three Months Ago)]]/ProxyCalc7[[#This Row],[PyPI Downloads (Six Months Ago)]] | L9: =ProxyCalc7[[#This Row],[PyPI Downloads (Prev Month)]]/ProxyCalc7[[#This Row],[PyPI Downloads (Six Months Ago)]] | M9: =ProxyCalc7[[#This Row],[PyPI Downloads (last month)]]/ProxyCalc7[[#This Row],[PyPI Downloads (Six Months Ago)]]
